<?xml version="1.0" encoding="utf-8"?>
<!-- This URDF was automatically created by SolidWorks to URDF Exporter! Originally created by Stephen Brawner (brawner@gmail.com)
     Commit Version: 1.6.0-1-g15f4949  Build Version: 1.6.7594.29634
     For more information, please see http://wiki.ros.org/sw_urdf_exporter -->
<robot
  name="Cartesian">
  <link
    name="base_link">
    <inertial>
      <origin
        xyz="-0.0055556 0 0.0094444"
        rpy="0 0 0" />
      <mass
        value="7.4258" />
      <inertia
        ixx="0.07605"
        ixy="1.4151E-19"
        ixz="0.00022919"
        iyy="0.013362"
        iyz="1.3595E-20"
        izz="0.088922" />
    </inertial>
    <visual>
      <origin
        xyz="0 0 0"
        rpy="0 0 0" />
      <geometry>
        <mesh
          filename="package://Cartesian/meshes/base_link.STL" />
      </geometry>
      <material
        name="">
        <color
          rgba="0.65098 0.61961 0.58824 1" />
      </material>
    </visual>
    <collision>
      <origin
        xyz="0 0 0"
        rpy="0 0 0" />
      <geometry>
        <mesh
          filename="package://Cartesian/meshes/base_link.STL" />
      </geometry>
    </collision>
  </link>
  <link
    name="tower_link">
    <inertial>
      <origin
        xyz="0 0 0.175"
        rpy="0 0 0" />
      <mass
        value="2.4753" />
      <inertia
        ixx="0.025454"
        ixy="4.1933E-21"
        ixz="2.0783E-34"
        iyy="0.025454"
        iyz="-2.3908E-19"
        izz="0.00037129" />
    </inertial>
    <visual>
      <origin
        xyz="0 0 0"
        rpy="0 0 0" />
      <geometry>
        <mesh
          filename="package://Cartesian/meshes/tower_link.STL" />
      </geometry>
      <material
        name="">
        <color
          rgba="0.65098 0.61961 0.58824 1" />
      </material>
    </visual>
    <collision>
      <origin
        xyz="0 0 0"
        rpy="0 0 0" />
      <geometry>
        <mesh
          filename="package://Cartesian/meshes/tower_link.STL" />
      </geometry>
    </collision>
  </link>
  <joint
    name="base_tower_prismatic_joint"
    type="prismatic">
    <origin
      xyz="0.05 -0.16 0.01"
      rpy="0 0 0" />
    <parent
      link="base_link" />
    <child
      link="tower_link" />
    <axis
      xyz="0 1 0" />
    <limit
      lower="-1"
      upper="1"
      effort="0"
      velocity="0" />
  </joint>
  <link
    name="shoulder_link">
    <inertial>
      <origin
        xyz="-0.0034615 -0.02 1.3878E-17"
        rpy="0 0 0" />
      <mass
        value="0.31432" />
      <inertia
        ixx="9.482E-05"
        ixy="1.625E-21"
        ixz="8.9762E-22"
        iyy="7.046E-05"
        iyz="3.0177E-21"
        izz="7.046E-05" />
    </inertial>
    <visual>
      <origin
        xyz="0 0 0"
        rpy="0 0 0" />
      <geometry>
        <mesh
          filename="package://Cartesian/meshes/shoulder_link.STL" />
      </geometry>
      <material
        name="">
        <color
          rgba="0.65098 0.61961 0.58824 1" />
      </material>
    </visual>
    <collision>
      <origin
        xyz="0 0 0"
        rpy="0 0 0" />
      <geometry>
        <mesh
          filename="package://Cartesian/meshes/shoulder_link.STL" />
      </geometry>
    </collision>
  </link>
  <joint
    name="tower_shoulder_prismatic_joint"
    type="prismatic">
    <origin
      xyz="0 0.028462 0.05"
      rpy="1.5708 0 1.5708" />
    <parent
      link="tower_link" />
    <child
      link="shoulder_link" />
    <axis
      xyz="0 1 0" />
    <limit
      lower="-1"
      upper="1"
      effort="0"
      velocity="0" />
  </joint>
  <link
    name="arm_link">
    <inertial>
      <origin
        xyz="2.7756E-17 -2.2551E-17 -0.15"
        rpy="0 0 0" />
      <mass
        value="2.1217" />
      <inertia
        ixx="0.016072"
        ixy="5.9379E-21"
        ixz="-1.364E-19"
        iyy="0.016072"
        iyz="-1.9871E-18"
        izz="0.00031825" />
    </inertial>
    <visual>
      <origin
        xyz="0 0 0"
        rpy="0 0 0" />
      <geometry>
        <mesh
          filename="package://Cartesian/meshes/arm_link.STL" />
      </geometry>
      <material
        name="">
        <color
          rgba="0.65098 0.61961 0.58824 1" />
      </material>
    </visual>
    <collision>
      <origin
        xyz="0 0 0"
        rpy="0 0 0" />
      <geometry>
        <mesh
          filename="package://Cartesian/meshes/arm_link.STL" />
      </geometry>
    </collision>
  </link>
  <joint
    name="shoulder_arm_prismatic_joint"
    type="prismatic">
    <origin
      xyz="0.021538 -0.02 0.02"
      rpy="0 0 0" />
    <parent
      link="shoulder_link" />
    <child
      link="arm_link" />
    <axis
      xyz="0 0 -1" />
    <limit
      lower="-1"
      upper="1"
      effort="0"
      velocity="0" />
  </joint>

   <link name="6_hand_limb">
<!--    <inertial>-->
<!--      <origin xyz="-0.0555917045329114 -7.25586546752172E-05 -0.00317411883668722" rpy="0 0 0" />-->

<!--    </inertial>-->
     <inertial>
      <mass value="0.727"/>
      <origin xyz="-0.0555917045329114 -7.25586546752172E-05 -0.00317411883668722" rpy="0 0 0" />
      <inertia ixx="0.0003453236187" ixy="0" ixz="0" iyy="0.0003453236187" iyz="0" izz="0.0005816"/>
    </inertial>

    <visual>
<!--      <origin xyz="0 0 0" rpy="0 0 0" />-->
      <geometry>
        <mesh filename="package://CartesianJaco/meshes/6_hand_limb.STL"/>
      </geometry>
    </visual>

    <collision>
      <origin xyz="0 0 0" rpy="0 0 0" />
      <geometry>
        <mesh filename="package://CartesianJaco/meshes/6_hand_limb.STL"/>
      </geometry>
    </collision>
  </link>


  <joint name="arm2ee" type="fixed">
    <origin xyz="-0.06590490 -0.034307921 0" rpy="-1.57 0 0.959931089" />
        <parent link="arm_link" />
        <child link="6_hand_limb" />
    <axis xyz="-1 0 0" />
  </joint>

  <link name="fingers_base_link">
    <inertial>
      <origin xyz="0 0 0" rpy="0 0 0" />
      <mass value="0.01"/>
<!--      <mass value="0.727"/>-->
      <inertia ixx="0.0003453236187" ixy="0" ixz="0" iyy="0.0003453236187" iyz="0" izz="0.0005816"/>
    </inertial>
  </link>

  <joint name="fingers_base_joint" type="fixed">
    <origin xyz="0 0 0" rpy="-1.57 1.57 1.57" />
        <parent link="6_hand_limb" />
        <child link="fingers_base_link" />
  </joint>




  <link name="7_finger_mount_index">
    <inertial>
      <origin xyz="0 0.00706399246397285 -0.00176078508424846" rpy="0 0 0" />
      <mass value="0.01"/>
      <inertia ixx="7.8999684e-07" ixy="0" ixz="0" iyy="7.8999684e-07" iyz="0" izz="8e-08"/>
<!--      <xacro:cyl_inertia mass="${0.006465/finger_mass_divider}" h="0.022" r="0.018"/>-->
    </inertial>
    <visual>
      <origin xyz="0 0 0" rpy="1.57 0 1.57" />
      <geometry>
        <mesh filename="package://CartesianJaco/meshes/7_finger_mount_index.STL" />
      </geometry>
      <material name="">
        <color rgba="0.5 0.5 0.5 1" />
      </material>
    </visual>
    <collision>
      <origin xyz="0 0 0" rpy="1.57 0 1.57" />
      <geometry>
        <mesh filename="package://CartesianJaco/meshes/7_finger_mount_index.STL" />
      </geometry>
    </collision>
  </link>

    <joint name="finger_mount_index_fixed" type="fixed">
    <origin xyz="-0.034  0.022 0.095" rpy="0 -0.2293 -0.191986" />
        <parent link="fingers_base_link" />
        <child link="7_finger_mount_index" />
    <axis xyz="0 0 0" />
  </joint>


  <link name="8_finger_index">
    <inertial>
      <origin xyz="-0.0181403689626489 0 0.00272470933850985" rpy="0 0 0" />
      <mass value="0.01"/>
<!--      <mass value="0.01"/>-->
      <inertia ixx="7.8999684e-07" ixy="0" ixz="0" iyy="7.8999684e-07" iyz="0" izz="8e-08"/>
<!--      <xacro:cyl_inertia mass="${0.01845/finger_mass_divider}" h="0.06" r="0.0135"/>-->
    </inertial>
<!--    <xacro:testSphere/>-->
    <visual>
      <origin xyz="0 0 0" rpy="3.14 1.17 0" />
      <geometry>
        <mesh filename="package://CartesianJaco/meshes/8_finger_index.STL" />
      </geometry>
<!--      <material name="">-->
<!--        <color rgba="0.50 0.50 0.50 1" />-->
<!--      </material>-->
    </visual>
    <collision>
      <origin xyz="0 0 0" rpy="3.14 1.17 0" />
      <geometry>
        <mesh filename="package://CartesianJaco/meshes/8_finger_index.STL" />
      </geometry>
    </collision>
  </link>
    <joint name="finger_joint_0" type="revolute">
<!--     <xacro:damping_fingers/>-->
    <origin xyz="-0.0276  0.0204 0.11" rpy="0 -0.34 -0.191986" />
        <parent link="fingers_base_link" />
        <child link="8_finger_index" />
    <axis xyz="0 1 0" />
        <limit lower="-0.0045" upper="1.05" effort="1.5" velocity="0.2" />
<!--<xacro:default_finger_limits/>-->
  </joint>



</robot>