<?xml version="1.0" ?>
<!-- =================================================================================== -->
<!-- |    This document was autogenerated by xacro from j2s7s300_standalone.xacro      | -->
<!-- |    EDITING THIS FILE BY HAND IS NOT RECOMMENDED                                 | -->
<!-- =================================================================================== -->
<!-- j2s7s300 refers to jaco v2 7DOF spherical 3fingers -->

<robot name="j2s7s300">

  <!-- for gazebo -->
  <link name="world"/>

  <link name="j2s7s300_link_base">
    <visual>
      <geometry>
        <mesh filename="meshes/base.dae"/>
      </geometry>
      <material name="d">
        <color rgba="0.2 0.2 0.2 1"/>
      </material>
    </visual>
    <collision>
      <geometry>
        <mesh filename="meshes/base.dae"/>
      </geometry>
    </collision>
    <inertial>
      <mass value="0.46784"/>
      <origin rpy="0 0 0" xyz="0 0 0.1255"/>
      <inertia ixx="0.000951270861568" ixy="0" ixz="0" iyy="0.000951270861568" iyz="0" izz="0.000374272"/>
    </inertial>
  </link>

  <link name="j2s7s300_link_1">
    <visual>
      <geometry>
        <mesh filename="meshes/shoulder.dae"/>
      </geometry>
      <material name="d"/>
    </visual>
    <visual>
      <geometry>
        <mesh filename="meshes/ring_big.STL"/>
      </geometry>

    </visual>
    <collision>
      <geometry>
        <mesh filename="meshes/shoulder.dae"/>
      </geometry>
    </collision>
    <inertial>
      <mass value="0.7477"/>
      <origin xyz="0 -0.002 -0.0605"/>
      <inertia ixx="0.00152031725204" ixy="0" ixz="0" iyy="0.00152031725204" iyz="0" izz="0.00059816"/>
    </inertial>
  </link>

  <link name="j2s7s300_link_2">
    <visual>
      <geometry>
        <mesh filename="meshes/arm_half_1.dae"/>
      </geometry>
      <material name="d"/>
    </visual>
    <visual>
      <geometry>
        <mesh filename="meshes/ring_big.STL"/>
      </geometry>
<!--      <material name="l"/>-->
    </visual>
    <collision>
      <geometry>
        <mesh filename="meshes/arm_half_1.dae"/>
      </geometry>
    </collision>
    <inertial>
      <mass value="0.8447"/>
      <origin xyz="0 -0.103563213 0"/>
      <inertia ixx="0.00247073761701" ixy="0" ixz="0" iyy="0.000380115" iyz="0" izz="0.00247073761701"/>
    </inertial>
  </link>

  <link name="j2s7s300_link_3">
    <visual>
      <geometry>
        <mesh filename="meshes/arm_half_2.dae"/>
      </geometry>

      <material name="d"/>
    </visual>
    <visual>
      <geometry>
        <mesh filename="meshes/ring_big.STL"/>
      </geometry>
    </visual>
    <collision>
      <geometry>
        <mesh filename="meshes/arm_half_2.dae"/>
      </geometry>
    </collision>
    <inertial>
      <mass value="0.8447"/>
      <origin xyz="0 0 -0.1022447445"/>
      <inertia ixx="0.00247073761701" ixy="0" ixz="0" iyy="0.00247073761701" iyz="0" izz="0.000380115"/>
    </inertial>
  </link>

  <link name="j2s7s300_link_4">
    <visual>
      <geometry>
        <mesh filename="meshes/forearm.dae"/>
      </geometry>

      <material name="d"/>
    </visual>
    <visual>
      <geometry>
        <mesh filename="meshes/ring_small.STL"/>
      </geometry>
    </visual>
    <collision>
      <geometry>
        <mesh filename="meshes/forearm.dae"/>
      </geometry>
    </collision>
    <inertial>
      <mass value="0.6763"/>
      <origin xyz="0 0.081 -0.0086"/>
      <inertia ixx="0.00142022431908" ixy="0" ixz="0" iyy="0.000304335" iyz="0" izz="0.00142022431908"/>
    </inertial>
  </link>

  <link name="j2s7s300_link_5">
    <visual>
      <geometry>
        <mesh filename="meshes/wrist_spherical_1.dae"/>
      </geometry>
      <material name="d"/>
    </visual>
    <visual>
      <geometry>
        <mesh filename="meshes/ring_small.STL"/>
      </geometry>
    </visual>
    <collision>
      <geometry>
        <mesh filename="meshes/wrist_spherical_1.dae"/>
      </geometry>
    </collision>
    <inertial>
      <mass value="0.463"/>
      <origin xyz="0 0.0028848942 -0.0541932613"/>
      <inertia ixx="0.0004321316048" ixy="0" ixz="0" iyy="0.0004321316048" iyz="0" izz="9.26e-05"/>
    </inertial>
  </link>

  <link name="j2s7s300_link_6">
    <visual>
      <geometry>
        <mesh filename="meshes/wrist_spherical_2.dae"/>
      </geometry>
      <material name="d"/>
    </visual>
    <visual>
      <geometry>
        <mesh filename="meshes/ring_small.STL"/>
      </geometry>
    </visual>
    <collision>
      <geometry>
        <mesh filename="meshes/wrist_spherical_2.dae"/>
      </geometry>
    </collision>
    <inertial>
      <mass value="0.463"/>
      <origin xyz="0 0.0497208855 -0.0028562765"/>
      <inertia ixx="0.0004321316048" ixy="0" ixz="0" iyy="9.26e-05" iyz="0" izz="0.0004321316048"/>
    </inertial>
  </link>

  <link name="j2s7s300_link_7">
    <visual>
      <geometry>
        <mesh filename="meshes/hand_3finger.dae"/>
      </geometry>
      <material name="d">
      </material>
    </visual>
    <visual>
      <geometry>
        <mesh filename="meshes/ring_small.STL"/>
      </geometry>
    </visual>
    <collision>
      <geometry>
        <mesh filename="meshes/hand_3finger.dae"/>
      </geometry>
    </collision>
    <inertial>
      <mass value="0.727"/>
      <origin xyz="0 0 -0.06"/>
      <inertia ixx="0.0003453236187" ixy="0" ixz="0" iyy="0.0003453236187" iyz="0" izz="0.0005816"/>
    </inertial>
  </link>

  <link name="j2s7s300_end_effector">
<!--    <visual>-->
<!--        <geometry>-->
<!--            <cylinder radius="1" length="0.5"/>-->
<!--        </geometry>-->
<!--    </visual>-->

<!--    <collision>-->
<!--        <geometry>-->
<!--            <cylinder radius="1" length="0.5"/>-->
<!--        </geometry>-->
<!--    </collision>-->

    <inertial>
      <mass value="0.001"/>
      <origin xyz="0 0 0"/>
      <inertia ixx="0.000001" ixy="0" ixz="0" iyy="0.000001" iyz="0" izz="0.000001"/>
    </inertial>

  </link>

  <link name="j2s7s300_link_finger_1">
    <visual>
      <geometry>
        <mesh filename="meshes/finger_proximal.dae"/>
      </geometry>
      <material name="f1">
        <color rgba="1 1 1 1"/>
      </material>
    </visual>
    <collision>
      <geometry>
        <mesh filename="meshes/finger_proximal.dae"/>
      </geometry>
    </collision>
    <inertial>
      <mass value="0.01"/>
      <origin xyz="0.022 0 0"/>
      <inertia ixx="7.8999684e-07" ixy="0" ixz="0" iyy="7.8999684e-07" iyz="0" izz="8e-08"/>
    </inertial>
  </link>

  <link name="j2s7s300_link_finger_tip_1">
    <visual>
      <geometry>
        <mesh filename="meshes/finger_distal.dae"/>
      </geometry>
      <material name="f1"/>
    </visual>
    <collision>
      <geometry>
        <mesh filename="meshes/finger_distal.dae"/>
      </geometry>
    </collision>
    <inertial>
      <mass value="0.01"/>
      <origin xyz="0.022 0 0"/>
      <inertia ixx="7.8999684e-07" ixy="0" ixz="0" iyy="7.8999684e-07" iyz="0" izz="8e-08"/>
    </inertial>
  </link>

  <link name="j2s7s300_link_finger_2">
    <visual>
      <geometry>
        <mesh filename="meshes/finger_proximal.dae"/>
      </geometry>
      <material name="f1"/>
    </visual>
    <collision>
      <geometry>
        <mesh filename="meshes/finger_proximal.dae"/>
      </geometry>
    </collision>
    <inertial>
      <mass value="0.01"/>
      <origin xyz="0.022 0 0"/>
      <inertia ixx="7.8999684e-07" ixy="0" ixz="0" iyy="7.8999684e-07" iyz="0" izz="8e-08"/>
    </inertial>
  </link>

  <link name="j2s7s300_link_finger_tip_2">
    <visual>
      <geometry>
        <mesh filename="meshes/finger_distal.dae"/>
      </geometry>
      <material name="f1"/>
    </visual>
    <collision>
      <geometry>
        <mesh filename="meshes/finger_distal.dae"/>
      </geometry>
    </collision>
    <inertial>
      <mass value="0.01"/>
      <origin xyz="0.022 0 0"/>
      <inertia ixx="7.8999684e-07" ixy="0" ixz="0" iyy="7.8999684e-07" iyz="0" izz="8e-08"/>
    </inertial>
  </link>

  <link name="j2s7s300_link_finger_3">
    <visual>
      <geometry>
        <mesh filename="meshes/finger_proximal.dae"/>
      </geometry>
      <material name="f1"/>
    </visual>
    <collision>
      <geometry>
        <mesh filename="meshes/finger_proximal.dae"/>
      </geometry>
    </collision>
    <inertial>
      <mass value="0.01"/>
      <origin xyz="0.022 0 0"/>
      <inertia ixx="7.8999684e-07" ixy="0" ixz="0" iyy="7.8999684e-07" iyz="0" izz="8e-08"/>
    </inertial>
  </link>

  <link name="j2s7s300_link_finger_tip_3">
    <visual>
      <geometry>
        <mesh filename="meshes/finger_distal.dae"/>
      </geometry>
      <material name="f1"/>
    </visual>
    <collision>
      <geometry>
        <mesh filename="meshes/finger_distal.dae"/>
      </geometry>
    </collision>
    <inertial>
      <mass value="0.01"/>
      <origin xyz="0.022 0 0"/>
      <inertia ixx="7.8999684e-07" ixy="0" ixz="0" iyy="7.8999684e-07" iyz="0" izz="8e-08"/>
    </inertial>
  </link>


  <joint name="j2s7s300_joint_1" type="continuous">
    <parent link="j2s7s300_link_base"/>
    <child link="j2s7s300_link_1"/>
    <axis xyz="0 0 1"/>
    <limit effort="2000" lower="-6.28318530718" upper="6.28318530718" velocity="1"/>
    <origin rpy="0 3.14159265359 0" xyz="0 0 0.15675"/>
    <dynamics damping="0.1" friction="10.0"/>
  </joint>

  <joint name="j2s7s300_joint_2" type="revolute">
    <parent link="j2s7s300_link_1"/>
    <child link="j2s7s300_link_2"/>
    <axis xyz="0 0 1"/>
    <limit effort="2000" lower="0.820304748437" upper="5.46288055874" velocity="1"/>
    <origin rpy="-1.57079632679 0 3.14159265359" xyz="0 0.0016 -0.11875"/>
    <dynamics damping="0.1" friction="10.0"/>
  </joint>

  <joint name="j2s7s300_joint_3" type="continuous">
    <parent link="j2s7s300_link_2"/>
    <child link="j2s7s300_link_3"/>
    <axis xyz="0 0 1"/>
    <limit effort="2000" lower="-6.28318530718" upper="6.28318530718" velocity="1"/>
    <origin rpy="-1.57079632679 0 0" xyz="0 -0.205 0"/>
    <dynamics damping="0.1" friction="10.0"/>
  </joint>

  <joint name="j2s7s300_joint_4" type="revolute">
    <parent link="j2s7s300_link_3"/>
    <child link="j2s7s300_link_4"/>
    <axis xyz="0 0 1"/>
    <limit effort="2000" lower="0.523598775598" upper="5.75958653158" velocity="1"/>
    <origin rpy="1.57079632679 0 3.14159265359" xyz="0 0 -0.205"/>
    <dynamics damping="0.1" friction="10.0"/>
  </joint>

  <joint name="j2s7s300_joint_5" type="continuous">
    <parent link="j2s7s300_link_4"/>
    <child link="j2s7s300_link_5"/>
    <axis xyz="0 0 1"/>
    <limit effort="2000" lower="-6.28318530718" upper="6.28318530718" velocity="1"/>
    <origin rpy="-1.57079632679 0 3.14159265359" xyz="0 0.2073 -0.0114"/>
    <dynamics damping="0.1" friction="10.0"/>
  </joint>

  <joint name="j2s7s300_joint_6" type="revolute">
    <parent link="j2s7s300_link_5"/>
    <child link="j2s7s300_link_6"/>
    <axis xyz="0 0 1"/>
    <limit effort="2000" lower="1.1344640138" upper="5.14872129338" velocity="1"/>
    <origin rpy="1.57079632679 0 3.14159265359" xyz="0 0 -0.10375"/>
    <dynamics damping="0.1" friction="10.0"/>
  </joint>

  <joint name="j2s7s300_joint_7" type="continuous">
    <parent link="j2s7s300_link_6"/>
    <child link="j2s7s300_link_7"/>
    <axis xyz="0 0 1"/>
    <limit effort="2000" lower="-6.28318530718" upper="6.28318530718" velocity="1"/>
    <origin rpy="-1.57079632679 0 3.14159265359" xyz="0 0.10375 0"/>
    <dynamics damping="0.1" friction="10.0"/>
  </joint>


  <joint name="j2s7s300_joint_end_effector" type="fixed">
    <parent link="j2s7s300_link_7"/>
    <child link="j2s7s300_end_effector"/>
    <axis xyz="0 0 0"/>
    <limit effort="2000" lower="0" upper="0" velocity="1"/>
    <origin rpy="3.14159265359 0 0" xyz="0 0 -0.1600"/>
  </joint>


  <joint name="j2s7s300_joint_finger_1" type="revolute">
    <parent link="j2s7s300_link_7"/>
    <child link="j2s7s300_link_finger_1"/>
    <axis xyz="0 0 1"/>
    <origin rpy="-1.570796327 .649262481663582 1.35961148639407" xyz="0.00279 0.03126 -0.11467"/>
    <limit effort="2000" lower="0" upper="2" velocity="1"/>
  </joint>

  <joint name="j2s7s300_joint_finger_tip_1" type="fixed">
    <parent link="j2s7s300_link_finger_1"/>
    <child link="j2s7s300_link_finger_tip_1"/>
    <axis xyz="0 0 1"/>
    <origin rpy="0 0 0" xyz="0.044 -0.003 0"/>
    <limit effort="2000" lower="0" upper="2" velocity="1"/>
  </joint>

  <joint name="j2s7s300_joint_finger_2" type="revolute">
    <parent link="j2s7s300_link_7"/>
    <child link="j2s7s300_link_finger_2"/>
    <axis xyz="0 0 1"/>
    <origin rpy="-1.570796327 .649262481663582 -1.38614049188413" xyz="0.02226 -0.02707 -0.11482"/>
    <limit effort="2000" lower="0" upper="2" velocity="1"/>
  </joint>

  <joint name="j2s7s300_joint_finger_tip_2" type="fixed">
    <parent link="j2s7s300_link_finger_2"/>
    <child link="j2s7s300_link_finger_tip_2"/>
    <axis xyz="0 0 1"/>
    <origin rpy="0 0 0" xyz="0.044 -0.003 0"/>
    <limit effort="2000" lower="0" upper="2" velocity="1"/>
  </joint>

  <joint name="j2s7s300_joint_finger_3" type="revolute">
    <parent link="j2s7s300_link_7"/>
    <child link="j2s7s300_link_finger_3"/>
    <axis xyz="0 0 1"/>
    <origin rpy="-1.570796327 .649262481663582 -1.75545216211587" xyz="-0.02226 -0.02707 -0.11482"/>
    <limit effort="2000" lower="0" upper="2" velocity="1"/>
  </joint>

  <joint name="j2s7s300_joint_finger_tip_3" type="fixed">
    <parent link="j2s7s300_link_finger_3"/>
    <child link="j2s7s300_link_finger_tip_3"/>
    <axis xyz="0 0 1"/>
    <origin rpy="0 0 0" xyz="0.044 -0.003 0"/>
    <limit effort="2000" lower="0" upper="2" velocity="1"/>
  </joint>

  <link name="bolt">
    <visual>
        <geometry>
            <cylinder radius="0.0042" length="0.11"/>
        </geometry>
        <material name="bolt">
          <color rgba="0.4 0.4 0.4 1"/>
        </material>
    </visual>

    <collision>
        <geometry>
            <cylinder radius="0.0042" length="0.11"/>
        </geometry>
    </collision>
  </link>

  <joint name="bolt_robot" type="fixed">
    <parent link="j2s7s300_end_effector"/>
    <child link="bolt"/>
    <axis xyz="0 0 1"/>
    <origin rpy="0 0 0" xyz="-0.013 -0.005 0.06"/> <!-- [+-0.005 +-0.003 +-0.01]-->
      <!--  x=  -0.01 -> -0.02-->
    <limit effort="2000" lower="0" upper="2" velocity="1"/>
  </joint>


  <joint name="connect_root_and_world" type="fixed">
    <child link="j2s7s300_link_base"/>
    <parent link="world"/>
    <origin rpy="0 0 0" xyz="0 0 0"/>
  </joint>

    <link name="camera_mount_link">
        <visual>
            <geometry>
                <mesh filename="meshes/camera_mount.dae" scale="0.9 0.9 0.9"/>
            </geometry>
            <material name="d"/>
        </visual>

        <collision>
            <geometry>
                <mesh filename="meshes/camera_mount.stl" scale="0.9 0.9 0.9"/>
            </geometry>
        </collision>

        <inertial>
            <mass value="0.1"/>
            <inertia
                    ixx="0.0" ixy="0.0" ixz="0.0" iyy="0.0" iyz="0.0" izz="0.0"/>
        </inertial>

    </link>

    <joint name="camera_mount_joint" type="fixed">
        <parent link="j2s7s300_end_effector"/>
        <child link="camera_mount_link"/>
        <origin xyz="0 0 -0.15" rpy="0 1.57 3.5 "/>
    </joint>

  <link name="camera">
    <visual>
        <geometry>
<!--            <cylinder radius="0.005" length="0.2"/>-->
          <box size="0.03 0.08 0.03"/>
        </geometry>
      <origin rpy="0 0 0" xyz="-0.08 0 -0.15"/>
        <material name="camera">
          <color rgba="0.8 0.8 0.8 1"/>
        </material>
    </visual>

    <collision>
        <geometry>
          <box size="0.03 0.08 0.03"/>
        </geometry>
    </collision>
  </link>

  <joint name="camera_robot" type="fixed">
    <parent link="j2s7s300_end_effector"/>
    <child link="camera"/>
    <axis xyz="0 0 1"/>
<!--    <origin xyz="-0.1 0 -0.1" rpy="0 1.57 0"/>-->
    <origin xyz="0 0 0"  rpy="0 0 0.3"/>
      <!--  x=  -0.01 -> -0.02-->
    <limit effort="2000" lower="0" upper="2" velocity="1"/>
  </joint>



</robot>

