<?xml version="1.0" ?>
<!-- =================================================================================== -->
<!-- |    This document was autogenerated by xacro from jaco_robot.urdf.xacro          | -->
<!-- |    EDITING THIS FILE BY HAND IS NOT RECOMMENDED                                 | -->
<!-- =================================================================================== -->
<robot name="jaco_robot" xmlns:controller="http://playerstage.sourceforge.net/gazebo/xmlschema/#controller" xmlns:interface="http://playerstage.sourceforge.net/gazebo/xmlschema/#interface" xmlns:sensor="http://playerstage.sourceforge.net/gazebo/xmlschema/#sensor">
<!--  <link name="robot_root">-->
<!--  </link>-->
  <!-- fake cylinder which is actually a box -->
  <!--xacro:macro name="cyl_inertia" params="mass r h ">
      <mass value="${mass}"/>
      <inertia
      ixx="${mass / 12.0 * (r*r + h*h)}" ixy="0.0" ixz="0.0"
      iyy="${mass / 12.0 * (h*h + r*r)}" iyz="0.0"
      izz="${mass / 12.0 * (r*r + r*r)}"/>
  </xacro:macro-->
  <!-- ***************** MODEL CORRECTIONS ************************* -->
  <!-- *************************************************************** -->
  <!-- from measurements, pitch is -0.2293 -->
  <!-- MODEL_FIX transforms from wrist to finger mounts -->
  <!--<xacro:property name="f_thb_m_xyz" value=" 0.037  0.001  0.106" />
  <xacro:property name="f_idx_m_xyz" value="-0.034  0.022 0.106" />
  <xacro:property name="f_pnk_m_xyz" value="-0.034 -0.022 0.106" />
  <xacro:property name="f_thb_m_rpy" value="0 -0.2658 ${M_PI-0.226892}" /> 
  <xacro:property name="f_idx_m_rpy" value="0 -0.2293 -0.191986" />
  <xacro:property name="f_pnk_m_rpy" value="0 -0.2293 0.191986" />-->
  <link
    name="base_link">
    <inertial>
      <origin
        xyz="-0.0055556 0 0.0094444"
        rpy="0 0 0" />
      <mass
        value="7.4258" />
      <inertia
        ixx="0.07605"
        ixy="1.4151E-19"
        ixz="0.00022919"
        iyy="0.013362"
        iyz="1.3595E-20"
        izz="0.088922" />
    </inertial>
    <visual>
      <origin
        xyz="0 0 0"
        rpy="0 0 0" />
      <geometry>
        <mesh
          filename="package://jaco_description/meshes/cart/base_link.STL" />
      </geometry>
      <material
        name="">
        <color
          rgba="0.65098 0.61961 0.58824 1" />
      </material>
    </visual>
    <collision>
      <origin
        xyz="0 0 0"
        rpy="0 0 0" />
      <geometry>
        <mesh
          filename="package://jaco_description/meshes/cart/base_link.STL" />
      </geometry>
    </collision>
  </link>
  <link
    name="tower_link">
    <inertial>
      <origin
        xyz="0 0 0.175"
        rpy="0 0 0" />
      <mass
        value="2.4753" />
      <inertia
        ixx="0.025454"
        ixy="4.1933E-21"
        ixz="2.0783E-34"
        iyy="0.025454"
        iyz="-2.3908E-19"
        izz="0.00037129" />
    </inertial>
    <visual>
      <origin
        xyz="0 0 0"
        rpy="0 0 0" />
      <geometry>
        <mesh
          filename="package://jaco_description/meshes/cart/tower_link.STL" />
      </geometry>
      <material
        name="">
        <color
          rgba="0.65098 0.61961 0.58824 1" />
      </material>
    </visual>
    <collision>
      <origin
        xyz="0 0 0"
        rpy="0 0 0" />
      <geometry>
        <mesh
          filename="package://jaco_description/meshes/cart/tower_link.STL" />
      </geometry>
    </collision>
  </link>
  <joint
    name="base_tower_prismatic_joint"
    type="prismatic">
    <origin
      xyz="0.05 -0.16 0.01"
      rpy="0 0 0" />
    <parent
      link="base_link" />
    <child
      link="tower_link" />
    <axis
      xyz="0 1 0" />
    <limit
      lower="-1"
      upper="1"
      effort="0"
      velocity="0" />
  </joint>
  <link
    name="shoulder_link">
    <inertial>
      <origin
        xyz="-0.0034615 -0.02 1.3878E-17"
        rpy="0 0 0" />
      <mass
        value="0.31432" />
      <inertia
        ixx="9.482E-05"
        ixy="1.625E-21"
        ixz="8.9762E-22"
        iyy="7.046E-05"
        iyz="3.0177E-21"
        izz="7.046E-05" />
    </inertial>
    <visual>
      <origin
        xyz="0 0 0"
        rpy="0 0 0" />
      <geometry>
        <mesh
          filename="package://jaco_description/meshes/cart/shoulder_link.STL" />
      </geometry>
      <material
        name="">
        <color
          rgba="0.65098 0.61961 0.58824 1" />
      </material>
    </visual>
    <collision>
      <origin
        xyz="0 0 0"
        rpy="0 0 0" />
      <geometry>
        <mesh
          filename="package://jaco_description/meshes/cart/shoulder_link.STL" />
      </geometry>
    </collision>
  </link>
  <joint
    name="tower_shoulder_prismatic_joint"
    type="prismatic">
    <origin
      xyz="0 0.028462 0.05"
      rpy="1.5708 0 1.5708" />
    <parent
      link="tower_link" />
    <child
      link="shoulder_link" />
    <axis
      xyz="0 1 0" />
    <limit
      lower="-1"
      upper="1"
      effort="0"
      velocity="0" />
  </joint>
  <link
    name="arm_link">
    <inertial>
      <origin
        xyz="2.7756E-17 -2.2551E-17 -0.15"
        rpy="0 0 0" />
      <mass
        value="2.1217" />
      <inertia
        ixx="0.016072"
        ixy="5.9379E-21"
        ixz="-1.364E-19"
        iyy="0.016072"
        iyz="-1.9871E-18"
        izz="0.00031825" />
    </inertial>
    <visual>
      <origin
        xyz="0 0 0"
        rpy="0 0 0" />
      <geometry>
        <mesh
          filename="package://jaco_description/meshes/cart/arm_link.STL" scale="0.01 0.01 0.01" />
      </geometry>
      <material
        name="">
        <color
          rgba="0.65098 0.61961 0.58824 1" />
      </material>
    </visual>
    <collision>
      <origin
        xyz="0 0 0"
        rpy="0 0 0" />
      <geometry>
        <mesh
          filename="package://jaco_description/meshes/cart/arm_link.STL" scale="0.01 0.01 0.01" />
      </geometry>
    </collision>
  </link>
  <joint
    name="shoulder_arm_prismatic_joint"
    type="prismatic">
    <origin
      xyz="0.021538 -0.02 0.02"
      rpy="0 0 0" />
    <parent
      link="shoulder_link" />
    <child
      link="arm_link" />
    <axis
      xyz="0 0 -1" />
    <limit
      lower="-1"
      upper="1"
      effort="0"
      velocity="0" />
  </joint>
  <joint name="jaco_arm_joint" type="fixed">
    <origin rpy="0 0 0" xyz="0 0 0"/>
    <parent link="arm_link"/>
    <child link="jaco_0_baseA"/>
  </joint>




  <link name="jaco_0_baseA">
    <inertial>
      <origin rpy="0 0 0" xyz="0 0 0.03"/>
      <mass value="0.5688"/>
      <inertia ixx="0.00034928920283759993" ixy="0" ixz="0" iyy="0.00034928920283759993" iyz="0" izz="0.0003685823999999999"/>
    </inertial>
    <visual>
      <origin rpy="0 0 0" xyz="0 0 0"/>
      <geometry>
        <mesh filename="package://jaco_description/meshes/jaco2/0_baseA.STL" scale="0.01 0.01 0.01"/>
      </geometry>
      <material name="d"/>
    </visual>
<!--    <collision>-->
<!--      <origin rpy="0 0 0" xyz="0 0 0"/>-->
<!--      <geometry>-->
<!--        <mesh filename="package://jaco_description/meshes/jaco2/0_baseA.STL"/>-->
<!--      </geometry>-->
<!--    </collision>-->
  </link>
  <link name="jaco_6_hand_limb">
    <inertial>
      <origin rpy="0 0 0" xyz="-0.0555917045329114 -7.25586546752172E-05 -0.00317411883668722"/>
      <mass value="0.2"/>
      <inertia ixx="0.0007852635256" ixy="0" ixz="0" iyy="0.0007852635256" iyz="0" izz="0.0012100000000000001"/>
    </inertial>
    <visual>
      <origin rpy="0 0 0" xyz="0 0 0"/>
      <geometry>
        <mesh filename="package://jaco_description/meshes/jaco2/6_hand_limb.STL" scale="1.0 1.0 1.0"/>
      </geometry>
      <material name="d">
        <color rgba="0.7 0.7 0.7 1"/>
      </material>
    </visual>
    <collision>
      <origin rpy="0 0 0" xyz="0 0 0"/>
      <geometry>
        <mesh filename="package://jaco_description/meshes/jaco2/6_hand_limb.STL" scale="1.0 1.0 1.0"/>
      </geometry>
    </collision>
  </link>
  <joint name="jaco_arm_5_joint" type="fixed">
    <origin rpy="1.57 -1.57 3" xyz="0 0 -0.3"/>
    <parent link="jaco_0_baseA"/>
    <child link="jaco_6_hand_limb"/>
  </joint>
  <link name="jaco_fingers_base_link">
    <inertial>
      <origin rpy="0 0 0" xyz="0 0 0"/>
      <mass value="0.001"/>
      <inertia ixx="3.33332e-08" ixy="0" ixz="0" iyy="3.33332e-08" iyz="0" izz="5.0000000000000004e-08"/>
    </inertial>
  </link>
  <!-- this joint is only to align the coordinate system with the kinova specification frame -->
  <joint name="jaco_fingers_base_joint" type="fixed">
    <origin rpy="-1.5707963267949 3.14159265358979 1.5707963267949" xyz="0 0 0"/>
    <parent link="jaco_6_hand_limb"/>
    <child link="jaco_fingers_base_link"/>
  </joint>
  <!-- ...........................  -->
  <!--      FINGERS          -->
  <!-- ...........................  -->
  <link name="jaco_7_finger_mount_index">
    <inertial>
      <origin rpy="0 0 0" xyz="0 0.00706399246397285 -0.00176078508424846"/>
      <mass value="0.006465"/>
      <inertia ixx="7.844168623200001e-07" ixy="0" ixz="0" iyy="7.844168623200001e-07" iyz="0" izz="1.0473299999999999e-06"/>
    </inertial>
    <visual>
      <origin rpy="1.5707963267949 0 1.5707963267949" xyz="0 0 0"/>
      <geometry>
        <mesh filename="package://jaco_description/meshes/jaco2/7_finger_mount_index.STL"/>
      </geometry>
      <material name="f">
        <color rgba="0.9 0.9 0.9 0"/>
      </material>
    </visual>
    <collision>
      <origin rpy="1.5707963267949 0 1.5707963267949" xyz="0 0 0"/>
      <geometry>
        <mesh filename="package://jaco_description/meshes/jaco2/7_finger_mount_index.STL"/>
      </geometry>
    </collision>
  </link>
  <joint name="jaco_finger_mount_index_fixed" type="fixed">
    <!--- remark 2014: damping greater than 0.1 (0.2) lead to model break downs when testing it bit by bit -->
    <!--- remark jan 2016: damping and friction higher than 0.005 required very high forces in order for the fingers
              to move at all, and then they mooved only slowly. -->
    <!--dynamics damping="0.1" friction="1.0"/-->
    <dynamics damping="0.005" friction="0.005"/>
    <origin rpy="0 -0.2293 -0.191986" xyz="-0.034  0.022 0.095"/>
    <parent link="jaco_fingers_base_link"/>
    <child link="jaco_7_finger_mount_index"/>
    <axis xyz="0 0 0"/>
  </joint>
  <!-- ...........................        -->
  <link name="jaco_8_finger_index">
    <inertial>
      <origin rpy="0 0 0" xyz="-0.0181403689626489 0 0.00272470933850985"/>
      <mass value="0.01845"/>
      <inertia ixx="6.3756026224875005e-06" ixy="0" ixz="0" iyy="6.3756026224875005e-06" iyz="0" izz="1.6812562500000002e-06"/>
    </inertial>
    <!--     <visual>
      <origin xyz="0 0 0" rpy="0 0 0" />
      <geometry>
        <sphere radius="0.005"/>
      </geometry>
      <material name="">
        <color rgba="0.10 0.10 0.10 1" />
      </material>
    </visual>
-->
    <visual>
      <origin rpy="3.14159265358979 1.1780972445 0" xyz="0 0 0"/>
      <geometry>
        <mesh filename="package://jaco_description/meshes/jaco2/8_finger_index.STL"/>
      </geometry>
      <material name="f"/>
    </visual>
    <collision>
      <origin rpy="3.14159265358979 1.1780972445 0" xyz="0 0 0"/>
      <geometry>
        <mesh filename="package://jaco_description/meshes/jaco2/8_finger_index.STL"/>
      </geometry>
    </collision>
  </link>
  <joint name="jaco_finger_joint_0" type="revolute">
    <!--- remark 2014: damping greater than 0.1 (0.2) lead to model break downs when testing it bit by bit -->
    <!--- remark jan 2016: damping and friction higher than 0.005 required very high forces in order for the fingers
              to move at all, and then they mooved only slowly. -->
    <!--dynamics damping="0.1" friction="1.0"/-->
    <dynamics damping="0.005" friction="0.005"/>
    <origin rpy="0 -0.34 -0.191986" xyz="-0.0276  0.0204 0.11"/>
    <parent link="jaco_fingers_base_link"/>
    <child link="jaco_8_finger_index"/>
    <axis xyz="0 1 0"/>
    <limit effort="1.5" lower="-0.0045" upper="1.05" velocity="0.2"/>
  </joint>
  <!-- ...........................        -->
  <link name="jaco_9_finger_index_tip">
    <inertial>
      <origin rpy="0 0 0" xyz="-0.01340812509202 -4.52693266978291E-07 0.0118561361126153"/>
      <mass value="0.0122"/>
      <inertia ixx="2.6850059266000007e-06" ixy="0" ixz="0" iyy="2.6850059266000007e-06" iyz="0" izz="8.784e-07"/>
    </inertial>
    <!--     <visual>
      <origin xyz="0 0 0" rpy="0 0 0" />
      <geometry>
        <sphere radius="0.005"/>
      </geometry>
      <material name="">
        <color rgba="0.10 0.10 0.10 1" />
      </material>
    </visual>
-->
    <visual>
      <origin rpy="0 1.5707963267949 3.14159265358979" xyz="0 0 0"/>
      <geometry>
        <mesh filename="package://jaco_description/meshes/jaco2/9_finger_index_tip.STL" scale="1 1 1"/>
      </geometry>
      <material name="f"/>
<!--        <color rgba="0.5 0.5 0.5 1"/>-->
<!--      </material>-->
    </visual>
    <collision>
      <origin rpy="0 1.5707963267949 3.14159265358979" xyz="0 0 0"/>
      <geometry>
        <mesh filename="package://jaco_description/meshes/jaco2/9_finger_index_tip.STL" scale="1 1 1"/>
      </geometry>
    </collision>
  </link>
  <joint name="jaco_finger_joint_1" type="fixed">
    <!--- remark 2014: damping greater than 0.1 (0.2) lead to model break downs when testing it bit by bit -->
    <!--- remark jan 2016: damping and friction higher than 0.005 required very high forces in order for the fingers
              to move at all, and then they mooved only slowly. -->
    <!--dynamics damping="0.1" friction="1.0"/-->
    <dynamics damping="0.005" friction="0.005"/>
    <origin rpy="0 0 0" xyz="0 0 0.0441"/>
    <parent link="jaco_8_finger_index"/>
    <child link="jaco_9_finger_index_tip"/>
  </joint>
  <!-- ...........................        -->
  <link name="jaco_7_finger_mount_thumb">
    <inertial>
      <origin rpy="0 0 0" xyz="-2.65251193937339E-07 0.00706398229186052 -0.00176078674955921"/>
      <mass value="0.006465"/>
      <inertia ixx="7.844168623200001e-07" ixy="0" ixz="0" iyy="7.844168623200001e-07" iyz="0" izz="1.0473299999999999e-06"/>
    </inertial>
    <visual>
      <origin rpy="1.5707963267949 0 1.5707963267949" xyz="0 0 0"/>
      <geometry>
        <mesh filename="package://jaco_description/meshes/jaco2/7_finger_mount_thumb.STL"/>
      </geometry>
      <material name="f"/>
<!--        <color rgba="0.50 0.50 0.50 1"/>-->
<!--      </material>-->
    </visual>
    <collision>
      <origin rpy="1.5707963267949 0 1.5707963267949" xyz="0 0 0"/>
      <geometry>
        <mesh filename="package://jaco_description/meshes/jaco2/7_finger_mount_thumb.STL"/>
      </geometry>
    </collision>
  </link>
  <joint name="jaco_finger_mount_thumb_fixed" type="fixed">
    <!--- remark 2014: damping greater than 0.1 (0.2) lead to model break downs when testing it bit by bit -->
    <!--- remark jan 2016: damping and friction higher than 0.005 required very high forces in order for the fingers
              to move at all, and then they mooved only slowly. -->
    <!--dynamics damping="0.1" friction="1.0"/-->
    <dynamics damping="0.005" friction="0.005"/>
    <origin rpy="0 -0.2658 2.91470065358979" xyz=" 0.037  0.001  0.095"/>
    <parent link="jaco_fingers_base_link"/>
    <child link="jaco_7_finger_mount_thumb"/>
  </joint>
  <!-- ...........................        -->
  <link name="jaco_8_finger_thumb">
    <inertial>
      <origin rpy="0 0 0" xyz="-0.0181403317517619 -3.13818432741766E-07 0.00272473343106584"/>
      <mass value="0.0184"/>
      <inertia ixx="6.3583245666e-06" ixy="0" ixz="0" iyy="6.3583245666e-06" iyz="0" izz="1.6766999999999998e-06"/>
    </inertial>
    <!--     <visual>
      <origin xyz="0 0 0" rpy="0 0 0" />
      <geometry>
        <sphere radius="0.005"/>
      </geometry>
      <material name="">
        <color rgba="0.10 0.10 0.10 1" />
      </material>
    </visual>
-->
    <visual>
      <origin rpy="3.14159265358979 1.1780972445 0" xyz="0 0 0"/>
      <geometry>
        <mesh filename="package://jaco_description/meshes/jaco2/8_finger_thumb.STL"/>
      </geometry>
      <material name="f"/>
<!--        <color rgba="0.5 0.5 0.5 1"/>-->
<!--      </material>-->
    </visual>
    <collision>
      <origin rpy="3.14159265358979 1.1780972445 0" xyz="0 0 0"/>
      <geometry>
        <mesh filename="package://jaco_description/meshes/jaco2/8_finger_thumb.STL"/>
      </geometry>
    </collision>
  </link>
  <joint name="jaco_finger_joint_2" type="revolute">
    <!--- remark 2014: damping greater than 0.1 (0.2) lead to model break downs when testing it bit by bit -->
    <!--- remark jan 2016: damping and friction higher than 0.005 required very high forces in order for the fingers
              to move at all, and then they mooved only slowly. -->
    <!--dynamics damping="0.1" friction="1.0"/-->
    <dynamics damping="0.005" friction="0.005"/>
    <origin rpy="0 -0.37 2.91470065358979" xyz=" 0.0319  0.003  0.11"/>
    <parent link="jaco_fingers_base_link"/>
    <child link="jaco_8_finger_thumb"/>
    <axis xyz="0 1 0"/>
    <limit effort="1.5" lower="-0.0045" upper="1.05" velocity="0.2"/>
  </joint>
  <!-- ...........................        -->
  <link name="jaco_9_finger_thumb_tip">
    <inertial>
      <origin rpy="0 0 0" xyz="-0.0134080639046228 -4.56622786070351E-07 0.0118561154422042"/>
      <mass value="0.0122"/>
      <inertia ixx="2.6850059266000007e-06" ixy="0" ixz="0" iyy="2.6850059266000007e-06" iyz="0" izz="8.784e-07"/>
    </inertial>
    <visual>
      <origin rpy="0 1.5707963267949 3.14159265358979" xyz="0 0 0"/>
      <geometry>
        <mesh filename="package://jaco_description/meshes/jaco2/9_finger_thumb_tip.STL" scale="1 1 1"/>
      </geometry>
      <material name="f"/>
<!--        <color rgba="0.5 0.5 0.5 1"/>-->
<!--      </material>-->
    </visual>
    <collision>
      <origin rpy="0 1.5707963267949 3.14159265358979" xyz="0 0 0"/>
      <geometry>
        <mesh filename="package://jaco_description/meshes/jaco2/9_finger_thumb_tip.STL" scale="1 1 1"/>
      </geometry>
    </collision>
  </link>
  <joint name="jaco_finger_joint_3" type="fixed">
    <!--- remark 2014: damping greater than 0.1 (0.2) lead to model break downs when testing it bit by bit -->
    <!--- remark jan 2016: damping and friction higher than 0.005 required very high forces in order for the fingers
              to move at all, and then they mooved only slowly. -->
    <!--dynamics damping="0.1" friction="1.0"/-->
    <dynamics damping="0.005" friction="0.005"/>
    <origin rpy="0 0 0" xyz="0 0 0.0441"/>
    <parent link="jaco_8_finger_thumb"/>
    <child link="jaco_9_finger_thumb_tip"/>
  </joint>
  <!-- ...........................        -->
  <link name="jaco_7_finger_mount_pinkie">
    <inertial>
      <origin rpy="0 0 0" xyz="0 0.00706399455294665 -0.00176077690193762"/>
      <mass value="0.00646"/>
      <inertia ixx="7.838101980799999e-07" ixy="0" ixz="0" iyy="7.838101980799999e-07" iyz="0" izz="1.0465199999999998e-06"/>
    </inertial>
    <visual>
      <origin rpy="1.5707963267949 0 1.5707963267949" xyz="0 0 0"/>
      <geometry>
        <mesh filename="package://jaco_description/meshes/jaco2/7_finger_mount_pinkie.STL"/>
      </geometry>
      <material name="f"/>
<!--        <color rgba="0.5 0.5 0.5 1"/>-->
<!--      </material>-->
    </visual>
    <collision>
      <origin rpy="1.5707963267949 0 1.5707963267949" xyz="0 0 0"/>
      <geometry>
        <mesh filename="package://jaco_description/meshes/jaco2/7_finger_mount_pinkie.STL"/>
      </geometry>
    </collision>
  </link>
  <joint name="jaco_finger_mount_pinkie_fixed" type="fixed">
    <!--- remark 2014: damping greater than 0.1 (0.2) lead to model break downs when testing it bit by bit -->
    <!--- remark jan 2016: damping and friction higher than 0.005 required very high forces in order for the fingers
              to move at all, and then they mooved only slowly. -->
    <!--dynamics damping="0.1" friction="1.0"/-->
    <dynamics damping="0.005" friction="0.005"/>
    <origin rpy="0 -0.2293 0.191986" xyz="-0.034 -0.022 0.095"/>
    <parent link="jaco_fingers_base_link"/>
    <child link="jaco_7_finger_mount_pinkie"/>
  </joint>
  <!-- ...........................        -->
  <link name="jaco_8_finger_pinkie">
    <inertial>
      <origin rpy="0 0 0" xyz="-0.0181404164708055 -2.87009015777565E-07 0.00272467774606585"/>
      <mass value="0.01845"/>
      <inertia ixx="6.3756026224875005e-06" ixy="0" ixz="0" iyy="6.3756026224875005e-06" iyz="0" izz="1.6812562500000002e-06"/>
    </inertial>
    <!--     <visual>
      <origin xyz="0 0 0" rpy="0 0 0" />
      <geometry>
        <sphere radius="0.005"/>
      </geometry>
      <material name="">
        <color rgba="0.10 0.10 0.10 1" />
      </material>
    </visual>
-->
    <visual>
      <origin rpy="3.14159265358979 1.1780972445 0" xyz="0 0 0"/>
      <geometry>
        <mesh filename="package://jaco_description/meshes/jaco2/8_finger_pinkie.STL"/>
      </geometry>
      <material name="f"/>
<!--        <color rgba="0.5 0.5 0.5 1"/>-->
<!--      </material>-->
    </visual>
    <collision>
      <origin rpy="3.14159265358979 1.1780972445 0" xyz="0 0 0"/>
      <geometry>
        <mesh filename="package://jaco_description/meshes/jaco2/8_finger_pinkie.STL"/>
      </geometry>
    </collision>
  </link>
  <joint name="jaco_finger_joint_4" type="revolute">
    <!--- remark 2014: damping greater than 0.1 (0.2) lead to model break downs when testing it bit by bit -->
    <!--- remark jan 2016: damping and friction higher than 0.005 required very high forces in order for the fingers
              to move at all, and then they mooved only slowly. -->
    <!--dynamics damping="0.1" friction="1.0"/-->
    <dynamics damping="0.005" friction="0.005"/>
    <origin rpy="0 -0.34 0.191986" xyz="-0.0276 -0.0204 0.11"/>
    <parent link="jaco_fingers_base_link"/>
    <child link="jaco_8_finger_pinkie"/>
    <axis xyz="0 1 0"/>
    <limit effort="1.5" lower="-0.0045" upper="1.05" velocity="0.2"/>
  </joint>
  <!-- ...........................        -->
  <link name="jaco_9_finger_pinkie_tip">
    <inertial>
      <origin rpy="0 0 0" xyz="-0.0134 0 0.01185"/>
      <mass value="0.0122"/>
      <inertia ixx="2.6850059266000007e-06" ixy="0" ixz="0" iyy="2.6850059266000007e-06" iyz="0" izz="8.784e-07"/>
    </inertial>
    <visual>
      <origin rpy="0 1.5707963267949 3.14159265358979" xyz="0 0 0"/>
      <geometry>
        <mesh filename="package://jaco_description/meshes/jaco2/9_finger_pinkie_tip.STL" scale="1 1 1"/>
      </geometry>
      <material name="f"/>
<!--        <color rgba="0.5 0.5 0.5 1"/>-->
<!--      </material>-->
    </visual>
    <collision>
      <origin rpy="0 1.5707963267949 3.14159265358979" xyz="0 0 0"/>
      <geometry>
        <mesh filename="package://jaco_description/meshes/jaco2/9_finger_pinkie_tip.STL" scale="1 1 1"/>
      </geometry>
    </collision>
  </link>
  <joint name="jaco_finger_joint_5" type="fixed">
    <!--- remark 2014: damping greater than 0.1 (0.2) lead to model break downs when testing it bit by bit -->
    <!--- remark jan 2016: damping and friction higher than 0.005 required very high forces in order for the fingers
              to move at all, and then they mooved only slowly. -->
    <!--dynamics damping="0.1" friction="1.0"/-->
    <dynamics damping="0.005" friction="0.005"/>
    <origin rpy="0 0 0" xyz="0 0 0.0441"/>
    <parent link="jaco_8_finger_pinkie"/>
    <child link="jaco_9_finger_pinkie_tip"/>
  </joint>




  <link name="camera_mount_link">
      <visual>
          <geometry>
              <mesh filename="package://jaco_description/meshes/camera/camera_mount.stl" scale="0.9 0.9 0.9"/>
          </geometry>
          <material name="d"/>
      </visual>
<!--        <collision>-->
<!--            <geometry>-->
<!--                <mesh filename="package://jaco_description/meshes/camera/camera_mount.stl" scale="0.9 0.9 0.9"/>-->
<!--            </geometry>-->
<!--        </collision>-->
      <inertial>
          <mass value="0.1"/>
          <inertia
                  ixx="0.0" ixy="0.0" ixz="0.0" iyy="0.0" iyz="0.0" izz="0.0"/>
      </inertial>
  </link>

  <joint name="camera_mount_joint" type="fixed">
        <parent link="jaco_0_baseA"/>
        <child link="camera_mount_link"/>
        <origin xyz="0 0 -0.3" rpy="0 1.57 1.57 "/>
    </joint>

  <link name="camera1">
    <visual>
        <geometry>
<!--            <cylinder radius="0.005" length="0.2"/>-->
          <box size="0.02 0.02 0.02"/>
        </geometry>
      <origin rpy="0 0 0" xyz="-0.08 0 -0.15"/>
        <material name="camera">
          <color rgba="0.2 0.2 0.2 1"/>
        </material>
    </visual>

  </link>

  <joint name="camera1_robot" type="fixed">
    <parent link="jaco_0_baseA"/>
    <child link="camera1"/>
    <axis xyz="0 0 1"/>
<!--    <origin xyz="-0.1 0 -0.1" rpy="0 1.57 0"/>-->
    <origin xyz="0.03 0 -0.15"  rpy="0 0 -1.57"/>
      <!--  x=  -0.01 -> -0.02-->
    <limit effort="2000" lower="0" upper="2" velocity="1"/>
  </joint>

  <link name="camera2">
    <visual>
        <geometry>
          <box size="0.02 0.02 0.02"/>
        </geometry>
      <origin rpy="0 0 0" xyz="-0.08 0 -0.15"/>
        <material name="camera"/>
    </visual>

  </link>

  <joint name="camera2_robot" type="fixed">
    <parent link="jaco_0_baseA"/>
    <child link="camera2"/>
    <axis xyz="0 0 1"/>
<!--    <origin xyz="-0.1 0 -0.1" rpy="0 1.57 0"/>-->
    <origin xyz="-0.03 0 -0.15"  rpy="0 0 -1.57"/>
      <!--  x=  -0.01 -> -0.02-->
  </joint>


  <link name="camera0">
    <visual>
        <geometry>
          <box size="0.03 0.08 0.002"/>
        </geometry>
      <origin rpy="0 0 0" xyz="-0.08 0 -0.15"/>
                <material name="camera0">
                  <color rgba="0.9 0.9 0.9 1"/>
                </material>
    </visual>

  </link>

  <joint name="camera0_robot" type="fixed">
    <parent link="jaco_0_baseA"/>
    <child link="camera0"/>
    <axis xyz="0 0 1"/>
    <origin xyz="0 -0.002 -0.14"  rpy="0 0 -1.57"/>
  </joint>

  <link name="bolt">
    <visual>
        <geometry>
            <cylinder radius="0.015" length="0.11"/>
        </geometry>
        <material name="bolt">
          <color rgba="0.8 0.8 0.8 1"/>
        </material>
    </visual>

    <collision>
        <geometry>
            <cylinder radius="0.0042" length="0.11"/>
        </geometry>
    </collision>
  </link>

  <joint name="bolt_robot" type="fixed">
    <parent link="jaco_fingers_base_link"/>
    <child link="bolt"/>
    <axis xyz="0 0 1"/>
    <origin rpy="0 0 0" xyz="-0.013 0.02 0.21"/> <!-- [+-0.005 +-0.003 +-0.01]-->
      <!--  x=  -0.01 -> -0.02-->
    <limit effort="2000" lower="0" upper="2" velocity="1"/>
  </joint>

</robot>

